<sdf version='1.7'>
  <model name='car1'>
    <link name='base_link'>
      <inertial>
        <pose>0.079767 -0 0.162077 0 -0 0</pose>
        <mass>26.1034</mass>
        <inertia>
          <ixx>2.45858</ixx>
          <ixy>9.41521e-17</ixy>
          <ixz>-0.806066</ixz>
          <iyy>5.17306</iyy>
          <iyz>-2.3529e-16</iyz>
          <izz>4.40287</izz>
        </inertia>
      </inertial>
      <collision name='base_link_collision'>
        <pose>0 0 0 0 -0 0</pose>
        <geometry>
          <mesh>
            <scale>1 1 1</scale>
            <uri>model://4WIS_Robot/meshes/base_link.STL</uri>
          </mesh>
        </geometry>
        <surface>
          <contact>
            <ode/>
          </contact>
          <friction>
            <ode/>
          </friction>
        </surface>
      </collision>
      <collision name='base_link_fixed_joint_lump__camera_collision_collision_1'>
        <pose>0.36 0 0.555 0 1.5708 0</pose>
        <geometry>
          <cylinder>
            <length>0.08</length>
            <radius>0.015</radius>
          </cylinder>
        </geometry>
      </collision>
      <collision name='base_link_fixed_joint_lump__imu_collision_collision_2'>
        <pose>0.36 0 0.555 0 -0 0</pose>
        <geometry>
          <box>
            <size>0.05 0.05 0.03</size>
          </box>
        </geometry>
      </collision>
      <collision name='base_link_fixed_joint_lump__lidar_link_base_link_collision_3'>
        <pose>0.36 0 0.52085 0 -0 0</pose>
        <geometry>
          <cylinder>
            <length>0.0717</length>
            <radius>0.0516</radius>
          </cylinder>
        </geometry>
      </collision>
      <visual name='base_link_visual'>
        <pose>0 0 0 0 -0 0</pose>
        <geometry>
          <mesh>
            <scale>1 1 1</scale>
            <uri>model://4WIS_Robot/meshes/base_link.STL</uri>
          </mesh>
        </geometry>
        <material>
          <script>
            <name>Gazebo/Blue</name>
            <uri>file://media/materials/scripts/gazebo.material</uri>
          </script>
        </material>
      </visual>
      <visual name='base_link_fixed_joint_lump__camera_visual_visual_1'>
        <pose>0.36 0 0.555 0 1.5708 0</pose>
        <geometry>
          <cylinder>
            <length>0.08</length>
            <radius>0.015</radius>
          </cylinder>
        </geometry>
      </visual>
      <visual name='base_link_fixed_joint_lump__imu_visual_visual_2'>
        <pose>0.36 0 0.555 0 -0 0</pose>
        <geometry>
          <box>
            <size>0.05 0.05 0.03</size>
          </box>
        </geometry>
      </visual>
      <visual name='base_link_fixed_joint_lump__lidar_link_base_link_visual_3'>
        <pose>0.36 0 0.485 0 -0 0</pose>
        <geometry>
          <mesh>
            <scale>1 1 1</scale>
            <uri>model://velodyne_description/meshes/VLP16_base_1.dae</uri>
          </mesh>
        </geometry>
      </visual>
      <visual name='base_link_fixed_joint_lump__lidar_link_base_link_visual_4'>
        <pose>0.36 0 0.485 0 -0 0</pose>
        <geometry>
          <mesh>
            <scale>1 1 1</scale>
            <uri>model://velodyne_description/meshes/VLP16_base_2.dae</uri>
          </mesh>
        </geometry>
      </visual>
      <visual name='base_link_fixed_joint_lump__lidar_link_visual_5'>
        <pose>0.36 0 0.485 0 -0 0</pose>
        <geometry>
          <mesh>
            <scale>1 1 1</scale>
            <uri>model://velodyne_description/meshes/VLP16_scan.dae</uri>
          </mesh>
        </geometry>
      </visual>
      <sensor name='base_collision_sensor' type='contact'>
        <always_on>1</always_on>
        <update_rate>100</update_rate>
        <contact>
          <collision>car1::base_link::base_link_collision</collision>
          <topic>__default_topic__</topic>
        </contact>
        <plugin name='base_bumper_controller' filename='libgazebo_ros_bumper.so'>
          <bumperTopicName>/car1/bumper_states</bumperTopicName>
          <frameName>car1/base_link</frameName>
        </plugin>
      </sensor>
      <sensor name='camera_node' type='camera'>
        <update_rate>30</update_rate>
        <camera name='head'>
          <horizontal_fov>1.0472</horizontal_fov>
          <image>
            <width>1280</width>
            <height>960</height>
            <format>R8G8B8</format>
          </image>
          <clip>
            <near>0.02</near>
            <far>100</far>
          </clip>
          <noise>
            <type>gaussian</type>
            <mean>0</mean>
            <stddev>0.007</stddev>
          </noise>
        </camera>
        <plugin name='kinect_camera_controller' filename='libgazebo_ros_camera.so'>
          <alwaysOn>1</alwaysOn>
          <updateRate>0.0</updateRate>
          <cameraName>/camera</cameraName>
          <imageTopicName>image_raw</imageTopicName>
          <cameraInfoTopicName>camera_info</cameraInfoTopicName>
          <frameName>car1/camera_link</frameName>
          <hackBaseline>0.07</hackBaseline>
          <distortionK1>0.0</distortionK1>
          <distortionK2>0.0</distortionK2>
          <distortionK3>0.0</distortionK3>
          <distortionT1>0.0</distortionT1>
          <distortionT2>0.0</distortionT2>
        </plugin>
        <pose>0.36 0 0.555 0 -0 0</pose>
      </sensor>
      <gravity>1</gravity>
      <sensor name='imu_imu_sensor' type='imu'>
        <always_on>1</always_on>
        <update_rate>100</update_rate>
        <visualize>1</visualize>
        <topic>__default_topic__</topic>
        <plugin name='imu_imu_plugin' filename='libgazebo_ros_imu_sensor.so'>
          <topicName>imu</topicName>
          <bodyName>imu_link</bodyName>
          <updateRateHZ>300.0</updateRateHZ>
          <gaussianNoise>0.0</gaussianNoise>
          <xyzOffset>0 0 0</xyzOffset>
          <rpyOffset>0 0 0</rpyOffset>
          <frameName>car1/imu_link</frameName>
        </plugin>
        <pose>0.36 0 0.555 0 -0 0</pose>
      </sensor>
      <sensor name='lidar_link-VLP16' type='gpu_ray'>
        <visualize>0</visualize>
        <update_rate>40</update_rate>
        <ray>
          <scan>
            <horizontal>
              <samples>440</samples>
              <resolution>1</resolution>
              <min_angle>-3.14159</min_angle>
              <max_angle>3.14159</max_angle>
            </horizontal>
            <vertical>
              <samples>16</samples>
              <resolution>1</resolution>
              <min_angle>-0.261799</min_angle>
              <max_angle>0.261799</max_angle>
            </vertical>
          </scan>
          <range>
            <min>0.1</min>
            <max>131</max>
            <resolution>0.001</resolution>
          </range>
          <noise>
            <type>gaussian</type>
            <mean>0</mean>
            <stddev>0.0001</stddev>
          </noise>
        </ray>
        <plugin name='gazebo_ros_laser_controller' filename='libgazebo_ros_velodyne_gpu_laser.so'>
          <topicName>velodyne_points</topicName>
          <frameName>lidar_link</frameName>
          <organize_cloud>0</organize_cloud>
          <min_range>0.01</min_range>
          <max_range>130.0</max_range>
          <gaussianNoise>0.0001</gaussianNoise>
        </plugin>
        <pose>0.36 0 0.5227 0 -0 0</pose>
      </sensor>
    </link>
    <joint name='fl_steer_joint' type='revolute'>
      <pose relative_to='base_link'>0.32 0.235 -0.01 0 -0 0</pose>
      <parent>base_link</parent>
      <child>fl_steer_link</child>
      <axis>
        <xyz>0 0 1</xyz>
        <limit>
          <lower>-0.55</lower>
          <upper>0.55</upper>
          <effort>100</effort>
          <velocity>1</velocity>
        </limit>
        <dynamics>
          <spring_reference>0</spring_reference>
          <spring_stiffness>0</spring_stiffness>
        </dynamics>
      </axis>
    </joint>
    <link name='fl_steer_link'>
      <pose relative_to='fl_steer_joint'>0 0 0 0 -0 0</pose>
      <inertial>
        <pose>0 0 -0.088728 0 -0 0</pose>
        <mass>25</mass>
        <inertia>
          <ixx>0.047904</ixx>
          <ixy>0</ixy>
          <ixz>0</ixz>
          <iyy>0.037562</iyy>
          <iyz>0</iyz>
          <izz>0.014192</izz>
        </inertia>
      </inertial>
      <collision name='fl_steer_link_collision'>
        <pose>0 0 0 0 -0 0</pose>
        <geometry>
          <mesh>
            <scale>1 1 1</scale>
            <uri>model://4WIS_Robot/meshes/fl_steer_link.STL</uri>
          </mesh>
        </geometry>
      </collision>
      <visual name='fl_steer_link_visual'>
        <pose>0 0 0 0 -0 0</pose>
        <geometry>
          <mesh>
            <scale>1 1 1</scale>
            <uri>model://4WIS_Robot/meshes/fl_steer_link.STL</uri>
          </mesh>
        </geometry>
      </visual>
    </link>
    <joint name='fl_drive_joint' type='revolute'>
      <pose relative_to='fl_steer_link'>0 0 -0.16 1.5708 -0 0</pose>
      <parent>fl_steer_link</parent>
      <child>fl_drive_link</child>
      <axis>
        <xyz>0 0 -1</xyz>
        <limit>
          <lower>-1e+16</lower>
          <upper>1e+16</upper>
        </limit>
        <dynamics>
          <spring_reference>0</spring_reference>
          <spring_stiffness>0</spring_stiffness>
        </dynamics>
      </axis>
    </joint>
    <link name='fl_drive_link'>
      <pose relative_to='fl_drive_joint'>0 0 0 0 -0 0</pose>
      <inertial>
        <pose>0 0 0 0 -0 0</pose>
        <mass>2.1666</mass>
        <inertia>
          <ixx>0.010578</ixx>
          <ixy>0</ixy>
          <ixz>0</ixz>
          <iyy>0.010578</iyy>
          <iyz>0</iyz>
          <izz>0.020276</izz>
        </inertia>
      </inertial>
      <collision name='fl_drive_link_collision'>
        <pose>0 0 0 0 -0 0</pose>
        <geometry>
          <mesh>
            <scale>1 1 1</scale>
            <uri>model://4WIS_Robot/meshes/fl_drive_link.STL</uri>
          </mesh>
        </geometry>
        <surface>
          <contact>
            <ode>
              <kp>100000</kp>
              <kd>10000</kd>
              <max_vel>5</max_vel>
              <min_depth>0.001</min_depth>
            </ode>
          </contact>
          <friction>
            <ode>
              <mu>1.5</mu>
              <mu2>1.5</mu2>
            </ode>
          </friction>
        </surface>
      </collision>
      <visual name='fl_drive_link_visual'>
        <pose>0 0 0 0 -0 0</pose>
        <geometry>
          <mesh>
            <scale>1 1 1</scale>
            <uri>model://4WIS_Robot/meshes/fl_drive_link.STL</uri>
          </mesh>
        </geometry>
        <material>
          <script>
            <name>Gazebo/Black</name>
            <uri>file://media/materials/scripts/gazebo.material</uri>
          </script>
        </material>
      </visual>
    </link>
    <joint name='fr_steer_joint' type='revolute'>
      <pose relative_to='base_link'>0.32 -0.235 -0.01 0 -0 0</pose>
      <parent>base_link</parent>
      <child>fr_steer_link</child>
      <axis>
        <xyz>0 0 1</xyz>
        <limit>
          <lower>-0.55</lower>
          <upper>0.55</upper>
          <effort>100</effort>
          <velocity>1</velocity>
        </limit>
        <dynamics>
          <spring_reference>0</spring_reference>
          <spring_stiffness>0</spring_stiffness>
        </dynamics>
      </axis>
    </joint>
    <link name='fr_steer_link'>
      <pose relative_to='fr_steer_joint'>0 0 0 0 -0 0</pose>
      <inertial>
        <pose>0 0 -0.088728 0 -0 0</pose>
        <mass>25</mass>
        <inertia>
          <ixx>0.047904</ixx>
          <ixy>0</ixy>
          <ixz>0</ixz>
          <iyy>0.037562</iyy>
          <iyz>0</iyz>
          <izz>0.014192</izz>
        </inertia>
      </inertial>
      <collision name='fr_steer_link_collision'>
        <pose>0 0 0 0 -0 0</pose>
        <geometry>
          <mesh>
            <scale>1 1 1</scale>
            <uri>model://4WIS_Robot/meshes/fr_steer_link.STL</uri>
          </mesh>
        </geometry>
      </collision>
      <visual name='fr_steer_link_visual'>
        <pose>0 0 0 0 -0 0</pose>
        <geometry>
          <mesh>
            <scale>1 1 1</scale>
            <uri>model://4WIS_Robot/meshes/fr_steer_link.STL</uri>
          </mesh>
        </geometry>
      </visual>
    </link>
    <joint name='fr_drive_joint' type='revolute'>
      <pose relative_to='fr_steer_link'>0 0 -0.16 1.5708 -0 0</pose>
      <parent>fr_steer_link</parent>
      <child>fr_drive_link</child>
      <axis>
        <xyz>0 0 -1</xyz>
        <limit>
          <lower>-1e+16</lower>
          <upper>1e+16</upper>
        </limit>
        <dynamics>
          <spring_reference>0</spring_reference>
          <spring_stiffness>0</spring_stiffness>
        </dynamics>
      </axis>
    </joint>
    <link name='fr_drive_link'>
      <pose relative_to='fr_drive_joint'>0 0 0 0 -0 0</pose>
      <inertial>
        <pose>0 0 0 0 -0 0</pose>
        <mass>2.1666</mass>
        <inertia>
          <ixx>0.010578</ixx>
          <ixy>0</ixy>
          <ixz>0</ixz>
          <iyy>0.010578</iyy>
          <iyz>0</iyz>
          <izz>0.020276</izz>
        </inertia>
      </inertial>
      <collision name='fr_drive_link_collision'>
        <pose>0 0 0 0 -0 0</pose>
        <geometry>
          <mesh>
            <scale>1 1 1</scale>
            <uri>model://4WIS_Robot/meshes/fr_drive_link.STL</uri>
          </mesh>
        </geometry>
        <surface>
          <contact>
            <ode>
              <kp>100000</kp>
              <kd>10000</kd>
              <max_vel>5</max_vel>
              <min_depth>0.001</min_depth>
            </ode>
          </contact>
          <friction>
            <ode>
              <mu>1.5</mu>
              <mu2>1.5</mu2>
            </ode>
          </friction>
        </surface>
      </collision>
      <visual name='fr_drive_link_visual'>
        <pose>0 0 0 0 -0 0</pose>
        <geometry>
          <mesh>
            <scale>1 1 1</scale>
            <uri>model://4WIS_Robot/meshes/fr_drive_link.STL</uri>
          </mesh>
        </geometry>
        <material>
          <script>
            <name>Gazebo/Black</name>
            <uri>file://media/materials/scripts/gazebo.material</uri>
          </script>
        </material>
      </visual>
    </link>
    <joint name='rl_steer_joint' type='revolute'>
      <pose relative_to='base_link'>-0.32 0.235 -0.01 0 -0 0</pose>
      <parent>base_link</parent>
      <child>rl_steer_link</child>
      <axis>
        <xyz>0 0 1</xyz>
        <limit>
          <lower>-0.55</lower>
          <upper>0.55</upper>
          <effort>100</effort>
          <velocity>1</velocity>
        </limit>
        <dynamics>
          <spring_reference>0</spring_reference>
          <spring_stiffness>0</spring_stiffness>
        </dynamics>
      </axis>
    </joint>
    <link name='rl_steer_link'>
      <pose relative_to='rl_steer_joint'>0 0 0 0 -0 0</pose>
      <inertial>
        <pose>0 0 -0.088728 0 -0 0</pose>
        <mass>25</mass>
        <inertia>
          <ixx>0.047904</ixx>
          <ixy>0</ixy>
          <ixz>0</ixz>
          <iyy>0.037562</iyy>
          <iyz>0</iyz>
          <izz>0.014192</izz>
        </inertia>
      </inertial>
      <collision name='rl_steer_link_collision'>
        <pose>0 0 0 0 -0 0</pose>
        <geometry>
          <mesh>
            <scale>1 1 1</scale>
            <uri>model://4WIS_Robot/meshes/rl_steer_link.STL</uri>
          </mesh>
        </geometry>
      </collision>
      <visual name='rl_steer_link_visual'>
        <pose>0 0 0 0 -0 0</pose>
        <geometry>
          <mesh>
            <scale>1 1 1</scale>
            <uri>model://4WIS_Robot/meshes/rl_steer_link.STL</uri>
          </mesh>
        </geometry>
      </visual>
    </link>
    <joint name='rl_drive_joint' type='revolute'>
      <pose relative_to='rl_steer_link'>0 0 -0.16 1.5708 -0 0</pose>
      <parent>rl_steer_link</parent>
      <child>rl_drive_link</child>
      <axis>
        <xyz>0 0 -1</xyz>
        <limit>
          <lower>-1e+16</lower>
          <upper>1e+16</upper>
        </limit>
        <dynamics>
          <spring_reference>0</spring_reference>
          <spring_stiffness>0</spring_stiffness>
        </dynamics>
      </axis>
    </joint>
    <link name='rl_drive_link'>
      <pose relative_to='rl_drive_joint'>0 0 0 0 -0 0</pose>
      <inertial>
        <pose>0 0 0 0 -0 0</pose>
        <mass>2.1666</mass>
        <inertia>
          <ixx>0.010578</ixx>
          <ixy>0</ixy>
          <ixz>0</ixz>
          <iyy>0.010578</iyy>
          <iyz>0</iyz>
          <izz>0.020276</izz>
        </inertia>
      </inertial>
      <collision name='rl_drive_link_collision'>
        <pose>0 0 0 0 -0 0</pose>
        <geometry>
          <mesh>
            <scale>1 1 1</scale>
            <uri>model://4WIS_Robot/meshes/rl_drive_link.STL</uri>
          </mesh>
        </geometry>
        <surface>
          <contact>
            <ode>
              <kp>100000</kp>
              <kd>10000</kd>
              <max_vel>5</max_vel>
              <min_depth>0.001</min_depth>
            </ode>
          </contact>
          <friction>
            <ode>
              <mu>1.5</mu>
              <mu2>1.5</mu2>
            </ode>
          </friction>
        </surface>
      </collision>
      <visual name='rl_drive_link_visual'>
        <pose>0 0 0 0 -0 0</pose>
        <geometry>
          <mesh>
            <scale>1 1 1</scale>
            <uri>model://4WIS_Robot/meshes/rl_drive_link.STL</uri>
          </mesh>
        </geometry>
        <material>
          <script>
            <name>Gazebo/Black</name>
            <uri>file://media/materials/scripts/gazebo.material</uri>
          </script>
        </material>
      </visual>
    </link>
    <joint name='rr_steer_joint' type='revolute'>
      <pose relative_to='base_link'>-0.32 -0.235 -0.01 0 -0 0</pose>
      <parent>base_link</parent>
      <child>rr_steer_link</child>
      <axis>
        <xyz>0 0 1</xyz>
        <limit>
          <lower>-0.55</lower>
          <upper>0.55</upper>
          <effort>100</effort>
          <velocity>1</velocity>
        </limit>
        <dynamics>
          <spring_reference>0</spring_reference>
          <spring_stiffness>0</spring_stiffness>
        </dynamics>
      </axis>
    </joint>
    <link name='rr_steer_link'>
      <pose relative_to='rr_steer_joint'>0 0 0 0 -0 0</pose>
      <inertial>
        <pose>0 0 -0.088728 0 -0 0</pose>
        <mass>25</mass>
        <inertia>
          <ixx>0.047904</ixx>
          <ixy>0</ixy>
          <ixz>0</ixz>
          <iyy>0.037562</iyy>
          <iyz>0</iyz>
          <izz>0.014192</izz>
        </inertia>
      </inertial>
      <collision name='rr_steer_link_collision'>
        <pose>0 0 0 0 -0 0</pose>
        <geometry>
          <mesh>
            <scale>1 1 1</scale>
            <uri>model://4WIS_Robot/meshes/rr_steer_link.STL</uri>
          </mesh>
        </geometry>
      </collision>
      <visual name='rr_steer_link_visual'>
        <pose>0 0 0 0 -0 0</pose>
        <geometry>
          <mesh>
            <scale>1 1 1</scale>
            <uri>model://4WIS_Robot/meshes/rr_steer_link.STL</uri>
          </mesh>
        </geometry>
      </visual>
    </link>
    <joint name='rr_drive_joint' type='revolute'>
      <pose relative_to='rr_steer_link'>0 0 -0.16 1.5708 -0 0</pose>
      <parent>rr_steer_link</parent>
      <child>rr_drive_link</child>
      <axis>
        <xyz>0 0 -1</xyz>
        <limit>
          <lower>-1e+16</lower>
          <upper>1e+16</upper>
        </limit>
        <dynamics>
          <spring_reference>0</spring_reference>
          <spring_stiffness>0</spring_stiffness>
        </dynamics>
      </axis>
    </joint>
    <link name='rr_drive_link'>
      <pose relative_to='rr_drive_joint'>0 0 0 0 -0 0</pose>
      <inertial>
        <pose>0 0 0 0 -0 0</pose>
        <mass>2.1666</mass>
        <inertia>
          <ixx>0.010578</ixx>
          <ixy>0</ixy>
          <ixz>0</ixz>
          <iyy>0.010578</iyy>
          <iyz>0</iyz>
          <izz>0.020276</izz>
        </inertia>
      </inertial>
      <collision name='rr_drive_link_collision'>
        <pose>0 0 0 0 -0 0</pose>
        <geometry>
          <mesh>
            <scale>1 1 1</scale>
            <uri>model://4WIS_Robot/meshes/rr_drive_link.STL</uri>
          </mesh>
        </geometry>
        <surface>
          <contact>
            <ode>
              <kp>100000</kp>
              <kd>10000</kd>
              <max_vel>5</max_vel>
              <min_depth>0.001</min_depth>
            </ode>
          </contact>
          <friction>
            <ode>
              <mu>1.5</mu>
              <mu2>1.5</mu2>
            </ode>
          </friction>
        </surface>
      </collision>
      <visual name='rr_drive_link_visual'>
        <pose>0 0 0 0 -0 0</pose>
        <geometry>
          <mesh>
            <scale>1 1 1</scale>
            <uri>model://4WIS_Robot/meshes/rr_drive_link.STL</uri>
          </mesh>
        </geometry>
        <material>
          <script>
            <name>Gazebo/Black</name>
            <uri>file://media/materials/scripts/gazebo.material</uri>
          </script>
        </material>
      </visual>
    </link>
    <plugin name='gazebo_ros_control' filename='libgazebo_ros_control.so'>
      <robotNamespace>/car1</robotNamespace>
    </plugin>
    <frame name='camera_joint' attached_to='base_link'>
      <pose>0.36 0 0.555 0 -0 0</pose>
    </frame>
    <frame name='camera_link' attached_to='camera_joint'/>
    <frame name='imu_joint' attached_to='base_link'>
      <pose>0.36 0 0.555 0 -0 0</pose>
    </frame>
    <frame name='imu_link' attached_to='imu_joint'/>
    <frame name='lidar_link_base_scan_joint' attached_to='lidar_link_base_link'>
      <pose>0 0 0.0377 0 -0 0</pose>
    </frame>
    <frame name='lidar_link' attached_to='lidar_link_base_scan_joint'/>
    <frame name='lidar_link_base_mount_joint' attached_to='base_link'>
      <pose>0.36 0 0.485 0 -0 0</pose>
    </frame>
    <frame name='lidar_link_base_link' attached_to='lidar_link_base_mount_joint'/>
  </model>
</sdf>
