<?xml version="1.0" ?>
<!-- =================================================================================== -->
<!-- |    This document was autogenerated by xacro from car_4ws_4wd.urdf.xacro         | -->
<!-- |    EDITING THIS FILE BY HAND IS NOT RECOMMENDED                                 | -->
<!-- =================================================================================== -->
<robot name="car1">
  <gazebo>
    <disableFixedJointLumping>true</disableFixedJointLumping>
  </gazebo>
  <!--
    Lidar dummy mount (visual + collision + inertial + gazebo material)
    Usage:
      <xacro:lidar_mount parent="base_link"
                         prefix="lidar"
                         xyz="0.66 0 0.635"
                         rpy="0 0 0"/>
  -->
  <!--
    IMU dummy mount (visual + collision + gazebo material)
    Usage:
      <xacro:imu_mount parent="lidar_body"
                       prefix="imu"
                       xyz="0 0 0.1"
                       rpy="0 0 0"
                       size="0.05 0.05 0.03"/>
  -->
  <!--
    Gazebo IMU sensor + gazebo_ros_imu_sensor plugin
    Usage example:
      <xacro:imu_sensor_gazebo reference="imu_link"
                               prefix="imu"
                               topic="imu"
                               frame="imu"
                               update_rate="100"
                               plugin_update_hz="300.0"
                               noise="0.0"
                               xyz_offset="0 0 0"
                               rpy_offset="0 0 0"/>
  -->
  <!--
    Gazebo RGB camera sensor macro (keeps your original parameters).
    Usage:
      <xacro:camera_sensor_gazebo reference="gazebo_camera_link"
                                  camera_name="/camera"
                                  image_topic="image_raw"
                                  info_topic="camera_info"
                                  frame="camera_link"/>
  -->
  <!-- <link name="base"/>
  <joint name="base_joint" type="fixed">
    <parent link="base"/>
    <child link="base_link"/>
    <origin xyz="0 0 0.3" rpy="0 0 0"/>
  </joint> -->
  <link name="base_link">
    <inertial>
      <origin rpy="0 0 0" xyz="-0.00117586528514695 -4.30552833609457E-17 0.05"/>
      <mass value="20.2533565247656"/>
      <inertia ixx="1.311634309655" ixy="1.64735322115376E-16" ixz="0.0137789561118299" iyy="3.43401128074704" iyz="-1.3755764102141E-16" izz="3.79965514788602"/>
    </inertial>
    <visual>
      <origin rpy="0 0 0" xyz="0 0 0"/>
      <geometry>
        <mesh filename="package://4WIS_Robot/meshes/base_link.STL"/>
      </geometry>
      <material name="">
        <color rgba="0.392156862745098 0.384313725490196 1 1"/>
      </material>
    </visual>
    <collision>
      <origin rpy="0 0 0" xyz="0 0 0"/>
      <geometry>
        <mesh filename="package://4WIS_Robot/meshes/base_link.STL"/>
      </geometry>
    </collision>
  </link>
  <gazebo reference="base_link">
    <material>Gazebo/Blue</material>
  </gazebo>
  <link name="fl_steer_link">
    <inertial>
      <origin rpy="0 0 0" xyz="5.5511E-17 0 -0.088728"/>
      <mass value="25"/>
      <inertia ixx="0.047904" ixy="0" ixz="0" iyy="0.037562" iyz="0" izz="0.014192"/>
    </inertial>
    <visual>
      <origin rpy="0 0 0" xyz="0 0 0"/>
      <geometry>
        <mesh filename="package://4WIS_Robot/meshes/fl_steer_link.STL"/>
      </geometry>
      <material name="">
        <color rgba="1 0.96078 0.90588 1"/>
      </material>
    </visual>
    <collision>
      <origin rpy="0 0 0" xyz="0 0 0"/>
      <geometry>
        <mesh filename="package://4WIS_Robot/meshes/fl_steer_link.STL"/>
      </geometry>
    </collision>
  </link>
  <joint name="fl_steer_joint" type="revolute">
    <origin rpy="0 0 0" xyz="0.32 0.235 -0.01"/>
    <parent link="base_link"/>
    <child link="fl_steer_link"/>
    <axis xyz="0 0 1"/>
    <limit effort="100" lower="-0.55" upper="0.55" velocity="1"/>
  </joint>
  <link name="fl_drive_link">
    <inertial>
      <origin rpy="0 0 0" xyz="0 0 0"/>
      <mass value="2.1666"/>
      <inertia ixx="0.010578" ixy="0" ixz="0" iyy="0.010578" iyz="0" izz="0.020276"/>
    </inertial>
    <visual>
      <origin rpy="0 0 0" xyz="0 0 0"/>
      <geometry>
        <mesh filename="package://4WIS_Robot/meshes/fl_drive_link.STL"/>
      </geometry>
      <material name="">
        <color rgba="0 0 0 1"/>
      </material>
    </visual>
    <collision>
      <origin rpy="0 0 0" xyz="0 0 0"/>
      <geometry>
        <mesh filename="package://4WIS_Robot/meshes/fl_drive_link.STL"/>
      </geometry>
    </collision>
  </link>
  <joint name="fl_drive_joint" type="continuous">
    <origin rpy="1.5707963267948966 0 0" xyz="0 0 -0.16"/>
    <parent link="fl_steer_link"/>
    <child link="fl_drive_link"/>
    <axis xyz="0 0 -1"/>
  </joint>
  <gazebo reference="fl_drive_link">
    <mu1>1.5</mu1>
    <mu2>1.5</mu2>
    <kp>100000.0</kp>
    <kd>10000.0</kd>
    <minDepth>0.001</minDepth>
    <maxVel>5.0</maxVel>
    <material>Gazebo/Black</material>
  </gazebo>
  <transmission name="fl_steer_trans">
    <type>transmission_interface/SimpleTransmission</type>
    <joint name="fl_steer_joint">
      <hardwareInterface>hardware_interface/PositionJointInterface</hardwareInterface>
    </joint>
    <actuator name="fl_steer_motor">
      <mechanicalReduction>1</mechanicalReduction>
      <hardwareInterface>hardware_interface/PositionJointInterface</hardwareInterface>
    </actuator>
  </transmission>
  <transmission name="fl_drive_trans">
    <type>transmission_interface/SimpleTransmission</type>
    <joint name="fl_drive_joint">
      <hardwareInterface>hardware_interface/VelocityJointInterface</hardwareInterface>
    </joint>
    <actuator name="fl_drive_motor">
      <mechanicalReduction>1</mechanicalReduction>
      <hardwareInterface>hardware_interface/VelocityJointInterface</hardwareInterface>
    </actuator>
  </transmission>
  <link name="fr_steer_link">
    <inertial>
      <origin rpy="0 0 0" xyz="5.5511E-17 0 -0.088728"/>
      <mass value="25"/>
      <inertia ixx="0.047904" ixy="0" ixz="0" iyy="0.037562" iyz="0" izz="0.014192"/>
    </inertial>
    <visual>
      <origin rpy="0 0 0" xyz="0 0 0"/>
      <geometry>
        <mesh filename="package://4WIS_Robot/meshes/fr_steer_link.STL"/>
      </geometry>
      <material name="">
        <color rgba="1 0.96078 0.90588 1"/>
      </material>
    </visual>
    <collision>
      <origin rpy="0 0 0" xyz="0 0 0"/>
      <geometry>
        <mesh filename="package://4WIS_Robot/meshes/fr_steer_link.STL"/>
      </geometry>
    </collision>
  </link>
  <joint name="fr_steer_joint" type="revolute">
    <origin rpy="0 0 0" xyz="0.32 -0.235 -0.01"/>
    <parent link="base_link"/>
    <child link="fr_steer_link"/>
    <axis xyz="0 0 1"/>
    <limit effort="100" lower="-0.55" upper="0.55" velocity="1"/>
  </joint>
  <link name="fr_drive_link">
    <inertial>
      <origin rpy="0 0 0" xyz="0 0 0"/>
      <mass value="2.1666"/>
      <inertia ixx="0.010578" ixy="0" ixz="0" iyy="0.010578" iyz="0" izz="0.020276"/>
    </inertial>
    <visual>
      <origin rpy="0 0 0" xyz="0 0 0"/>
      <geometry>
        <mesh filename="package://4WIS_Robot/meshes/fr_drive_link.STL"/>
      </geometry>
      <material name="">
        <color rgba="0 0 0 1"/>
      </material>
    </visual>
    <collision>
      <origin rpy="0 0 0" xyz="0 0 0"/>
      <geometry>
        <mesh filename="package://4WIS_Robot/meshes/fr_drive_link.STL"/>
      </geometry>
    </collision>
  </link>
  <joint name="fr_drive_joint" type="continuous">
    <origin rpy="1.5707963267948966 0 0" xyz="0 0 -0.16"/>
    <parent link="fr_steer_link"/>
    <child link="fr_drive_link"/>
    <axis xyz="0 0 -1"/>
  </joint>
  <gazebo reference="fr_drive_link">
    <mu1>1.5</mu1>
    <mu2>1.5</mu2>
    <kp>100000.0</kp>
    <kd>10000.0</kd>
    <minDepth>0.001</minDepth>
    <maxVel>5.0</maxVel>
    <material>Gazebo/Black</material>
  </gazebo>
  <transmission name="fr_steer_trans">
    <type>transmission_interface/SimpleTransmission</type>
    <joint name="fr_steer_joint">
      <hardwareInterface>hardware_interface/PositionJointInterface</hardwareInterface>
    </joint>
    <actuator name="fr_steer_motor">
      <mechanicalReduction>1</mechanicalReduction>
      <hardwareInterface>hardware_interface/PositionJointInterface</hardwareInterface>
    </actuator>
  </transmission>
  <transmission name="fr_drive_trans">
    <type>transmission_interface/SimpleTransmission</type>
    <joint name="fr_drive_joint">
      <hardwareInterface>hardware_interface/VelocityJointInterface</hardwareInterface>
    </joint>
    <actuator name="fr_drive_motor">
      <mechanicalReduction>1</mechanicalReduction>
      <hardwareInterface>hardware_interface/VelocityJointInterface</hardwareInterface>
    </actuator>
  </transmission>
  <link name="rl_steer_link">
    <inertial>
      <origin rpy="0 0 0" xyz="5.5511E-17 0 -0.088728"/>
      <mass value="25"/>
      <inertia ixx="0.047904" ixy="0" ixz="0" iyy="0.037562" iyz="0" izz="0.014192"/>
    </inertial>
    <visual>
      <origin rpy="0 0 0" xyz="0 0 0"/>
      <geometry>
        <mesh filename="package://4WIS_Robot/meshes/rl_steer_link.STL"/>
      </geometry>
      <material name="">
        <color rgba="1 0.96078 0.90588 1"/>
      </material>
    </visual>
    <collision>
      <origin rpy="0 0 0" xyz="0 0 0"/>
      <geometry>
        <mesh filename="package://4WIS_Robot/meshes/rl_steer_link.STL"/>
      </geometry>
    </collision>
  </link>
  <joint name="rl_steer_joint" type="revolute">
    <origin rpy="0 0 0" xyz="-0.32 0.235 -0.01"/>
    <parent link="base_link"/>
    <child link="rl_steer_link"/>
    <axis xyz="0 0 1"/>
    <limit effort="100" lower="-0.55" upper="0.55" velocity="1"/>
  </joint>
  <link name="rl_drive_link">
    <inertial>
      <origin rpy="0 0 0" xyz="0 0 0"/>
      <mass value="2.1666"/>
      <inertia ixx="0.010578" ixy="0" ixz="0" iyy="0.010578" iyz="0" izz="0.020276"/>
    </inertial>
    <visual>
      <origin rpy="0 0 0" xyz="0 0 0"/>
      <geometry>
        <mesh filename="package://4WIS_Robot/meshes/rl_drive_link.STL"/>
      </geometry>
      <material name="">
        <color rgba="0 0 0 1"/>
      </material>
    </visual>
    <collision>
      <origin rpy="0 0 0" xyz="0 0 0"/>
      <geometry>
        <mesh filename="package://4WIS_Robot/meshes/rl_drive_link.STL"/>
      </geometry>
    </collision>
  </link>
  <joint name="rl_drive_joint" type="continuous">
    <origin rpy="1.5707963267948966 0 0" xyz="0 0 -0.16"/>
    <parent link="rl_steer_link"/>
    <child link="rl_drive_link"/>
    <axis xyz="0 0 -1"/>
  </joint>
  <gazebo reference="rl_drive_link">
    <mu1>1.5</mu1>
    <mu2>1.5</mu2>
    <kp>100000.0</kp>
    <kd>10000.0</kd>
    <minDepth>0.001</minDepth>
    <maxVel>5.0</maxVel>
    <material>Gazebo/Black</material>
  </gazebo>
  <transmission name="rl_steer_trans">
    <type>transmission_interface/SimpleTransmission</type>
    <joint name="rl_steer_joint">
      <hardwareInterface>hardware_interface/PositionJointInterface</hardwareInterface>
    </joint>
    <actuator name="rl_steer_motor">
      <mechanicalReduction>1</mechanicalReduction>
      <hardwareInterface>hardware_interface/PositionJointInterface</hardwareInterface>
    </actuator>
  </transmission>
  <transmission name="rl_drive_trans">
    <type>transmission_interface/SimpleTransmission</type>
    <joint name="rl_drive_joint">
      <hardwareInterface>hardware_interface/VelocityJointInterface</hardwareInterface>
    </joint>
    <actuator name="rl_drive_motor">
      <mechanicalReduction>1</mechanicalReduction>
      <hardwareInterface>hardware_interface/VelocityJointInterface</hardwareInterface>
    </actuator>
  </transmission>
  <link name="rr_steer_link">
    <inertial>
      <origin rpy="0 0 0" xyz="5.5511E-17 0 -0.088728"/>
      <mass value="25"/>
      <inertia ixx="0.047904" ixy="0" ixz="0" iyy="0.037562" iyz="0" izz="0.014192"/>
    </inertial>
    <visual>
      <origin rpy="0 0 0" xyz="0 0 0"/>
      <geometry>
        <mesh filename="package://4WIS_Robot/meshes/rr_steer_link.STL"/>
      </geometry>
      <material name="">
        <color rgba="1 0.96078 0.90588 1"/>
      </material>
    </visual>
    <collision>
      <origin rpy="0 0 0" xyz="0 0 0"/>
      <geometry>
        <mesh filename="package://4WIS_Robot/meshes/rr_steer_link.STL"/>
      </geometry>
    </collision>
  </link>
  <joint name="rr_steer_joint" type="revolute">
    <origin rpy="0 0 0" xyz="-0.32 -0.235 -0.01"/>
    <parent link="base_link"/>
    <child link="rr_steer_link"/>
    <axis xyz="0 0 1"/>
    <limit effort="100" lower="-0.55" upper="0.55" velocity="1"/>
  </joint>
  <link name="rr_drive_link">
    <inertial>
      <origin rpy="0 0 0" xyz="0 0 0"/>
      <mass value="2.1666"/>
      <inertia ixx="0.010578" ixy="0" ixz="0" iyy="0.010578" iyz="0" izz="0.020276"/>
    </inertial>
    <visual>
      <origin rpy="0 0 0" xyz="0 0 0"/>
      <geometry>
        <mesh filename="package://4WIS_Robot/meshes/rr_drive_link.STL"/>
      </geometry>
      <material name="">
        <color rgba="0 0 0 1"/>
      </material>
    </visual>
    <collision>
      <origin rpy="0 0 0" xyz="0 0 0"/>
      <geometry>
        <mesh filename="package://4WIS_Robot/meshes/rr_drive_link.STL"/>
      </geometry>
    </collision>
  </link>
  <joint name="rr_drive_joint" type="continuous">
    <origin rpy="1.5707963267948966 0 0" xyz="0 0 -0.16"/>
    <parent link="rr_steer_link"/>
    <child link="rr_drive_link"/>
    <axis xyz="0 0 -1"/>
  </joint>
  <gazebo reference="rr_drive_link">
    <mu1>1.5</mu1>
    <mu2>1.5</mu2>
    <kp>100000.0</kp>
    <kd>10000.0</kd>
    <minDepth>0.001</minDepth>
    <maxVel>5.0</maxVel>
    <material>Gazebo/Black</material>
  </gazebo>
  <transmission name="rr_steer_trans">
    <type>transmission_interface/SimpleTransmission</type>
    <joint name="rr_steer_joint">
      <hardwareInterface>hardware_interface/PositionJointInterface</hardwareInterface>
    </joint>
    <actuator name="rr_steer_motor">
      <mechanicalReduction>1</mechanicalReduction>
      <hardwareInterface>hardware_interface/PositionJointInterface</hardwareInterface>
    </actuator>
  </transmission>
  <transmission name="rr_drive_trans">
    <type>transmission_interface/SimpleTransmission</type>
    <joint name="rr_drive_joint">
      <hardwareInterface>hardware_interface/VelocityJointInterface</hardwareInterface>
    </joint>
    <actuator name="rr_drive_motor">
      <mechanicalReduction>1</mechanicalReduction>
      <hardwareInterface>hardware_interface/VelocityJointInterface</hardwareInterface>
    </actuator>
  </transmission>
  <!-- <xacro:lidar_mount parent="base_link" prefix="lidar" xyz="0.36 0 0.485" rpy="0 0 0"/>
  <xacro:lidar_gpu_ray reference="lidar_link" prefix="lidar" topic="velodyne_points" frame="lidar_link"/> -->
  <joint name="lidar_link_base_mount_joint" type="fixed">
    <origin rpy="0 0 0" xyz="0.36 0 0.485"/>
    <parent link="base_link"/>
    <child link="lidar_link_base_link"/>
  </joint>
  <link name="lidar_link_base_link">
    <inertial>
      <mass value="0.83"/>
      <origin xyz="0 0 0.03585"/>
      <inertia ixx="0.000908059425" ixy="0" ixz="0" iyy="0.000908059425" iyz="0" izz="0.0011049624"/>
    </inertial>
    <visual>
      <geometry>
        <mesh filename="package://velodyne_description/meshes/VLP16_base_1.dae"/>
      </geometry>
    </visual>
    <visual>
      <geometry>
        <mesh filename="package://velodyne_description/meshes/VLP16_base_2.dae"/>
      </geometry>
    </visual>
    <collision>
      <origin rpy="0 0 0" xyz="0 0 0.03585"/>
      <geometry>
        <cylinder length="0.0717" radius="0.0516"/>
      </geometry>
    </collision>
  </link>
  <joint name="lidar_link_base_scan_joint" type="fixed">
    <origin rpy="0 0 0" xyz="0 0 0.0377"/>
    <parent link="lidar_link_base_link"/>
    <child link="lidar_link"/>
  </joint>
  <link name="lidar_link">
    <inertial>
      <mass value="0.01"/>
      <origin xyz="0 0 0"/>
      <inertia ixx="1e-7" ixy="0" ixz="0" iyy="1e-7" iyz="0" izz="1e-7"/>
    </inertial>
    <visual>
      <origin xyz="0 0 -0.0377"/>
      <geometry>
        <mesh filename="package://velodyne_description/meshes/VLP16_scan.dae"/>
      </geometry>
    </visual>
  </link>
  <!-- Gazebo requires the velodyne_gazebo_plugins package -->
  <gazebo reference="lidar_link">
    <sensor name="lidar_link-VLP16" type="gpu_ray">
      <pose>0 0 0 0 0 0</pose>
      <visualize>false</visualize>
      <update_rate>40</update_rate>
      <ray>
        <scan>
          <horizontal>
            <samples>440</samples>
            <resolution>1</resolution>
            <min_angle>-3.141592653589793</min_angle>
            <max_angle>3.141592653589793</max_angle>
          </horizontal>
          <vertical>
            <samples>16</samples>
            <resolution>1</resolution>
            <min_angle>-0.2617993877991494</min_angle>
            <max_angle> 0.2617993877991494</max_angle>
          </vertical>
        </scan>
        <range>
          <min>0.1</min>
          <max>131.0</max>
          <resolution>0.001</resolution>
        </range>
        <noise>
          <type>gaussian</type>
          <mean>0.00</mean>
          <stddev>0.0001</stddev>
        </noise>
      </ray>
      <plugin filename="libgazebo_ros_velodyne_gpu_laser.so" name="gazebo_ros_laser_controller">
        <topicName>velodyne_points</topicName>
        <frameName>lidar_link</frameName>
        <organize_cloud>False</organize_cloud>
        <min_range>0.01</min_range>
        <max_range>130.0</max_range>
        <gaussianNoise>0.0001</gaussianNoise>
      </plugin>
    </sensor>
  </gazebo>
  <!-- parent -> imu -->
  <joint name="imu_joint" type="fixed">
    <parent link="base_link"/>
    <child link="imu_link"/>
    <origin rpy="0 0 0" xyz="0.36 0 0.555"/>
  </joint>
  <link name="imu_link">
    <visual name="imu_visual">
      <origin rpy="0 0 0" xyz="0 0 0"/>
      <geometry>
        <box size="0.05 0.05 0.03"/>
      </geometry>
      <material name="imu_mat">
        <color rgba="1.0 0.0 0.0 1.0"/>
      </material>
    </visual>
    <collision name="imu_collision">
      <origin rpy="0 0 0" xyz="0 0 0"/>
      <geometry>
        <box size="0.05 0.05 0.03"/>
      </geometry>
    </collision>
    <inertial>
      <origin rpy="0 0 0" xyz="0 0 0"/>
      <mass value="0.01"/>
      <inertia ixx="1e-5" ixy="0" ixz="0" iyy="1e-5" iyz="0" izz="1e-5"/>
    </inertial>
  </link>
  <gazebo reference="imu_link">
    <material>Gazebo/Red</material>
  </gazebo>
  <gazebo reference="imu_link">
    <gravity>True</gravity>
    <sensor name="imu_imu_sensor" type="imu">
      <always_on>True</always_on>
      <update_rate>100</update_rate>
      <visualize>True</visualize>
      <!-- 保持你原来的字段 -->
      <topic>__default_topic__</topic>
      <plugin filename="libgazebo_ros_imu_sensor.so" name="imu_imu_plugin">
        <topicName>imu</topicName>
        <bodyName>imu_link</bodyName>
        <updateRateHZ>300.0</updateRateHZ>
        <gaussianNoise>0.0</gaussianNoise>
        <xyzOffset>0 0 0</xyzOffset>
        <rpyOffset>0 0 0</rpyOffset>
        <frameName>car1/imu_link</frameName>
      </plugin>
      <pose>0 0 0 0 0 0</pose>
    </sensor>
  </gazebo>
  <!-- joint: parent -> camera link -->
  <joint name="camera_joint" type="fixed">
    <parent link="base_link"/>
    <child link="camera_link"/>
    <origin rpy="0 0 0" xyz="0.36 0 0.555"/>
  </joint>
  <link name="camera_link">
    <collision name="camera_collision">
      <origin rpy="0 1.5707963267948966 0" xyz="0 0 0"/>
      <geometry>
        <cylinder length="0.08" radius="0.015"/>
      </geometry>
    </collision>
    <!-- RViz uses this color -->
    <visual name="camera_visual">
      <origin rpy="0 1.5707963267948966 0" xyz="0 0 0"/>
      <geometry>
        <cylinder length="0.08" radius="0.015"/>
      </geometry>
      <material name="camera_mat">
        <!-- 固定一个深灰，和 Gazebo/DarkGrey 接近 -->
        <color rgba="0.3 0.3 0.3 1.0"/>
      </material>
    </visual>
    <inertial>
      <origin rpy="0 0 0" xyz="0 0 0"/>
      <mass value="5"/>
      <inertia ixx="0.01" ixy="0.0" ixz="0.0" iyy="0.01" iyz="0" izz="0.01"/>
    </inertial>
  </link>
  <!-- Gazebo uses this material -->
  <gazebo reference="camera_link">
    <material>Gazebo/DarkGrey</material>
  </gazebo>
  <!-- RGB Camera 60°: 1.0472 (note: your current horizontal_fov is 1.396) -->
  <gazebo reference="camera_link">
    <sensor name="camera_node" type="camera">
      <update_rate>30.0</update_rate>
      <camera name="head">
        <horizontal_fov>1.0472</horizontal_fov>
        <image>
          <width>1280</width>
          <height>960</height>
          <format>R8G8B8</format>
        </image>
        <clip>
          <near>0.02</near>
          <far>100</far>
        </clip>
        <noise>
          <type>gaussian</type>
          <mean>0.0</mean>
          <stddev>0.007</stddev>
        </noise>
      </camera>
      <plugin filename="libgazebo_ros_camera.so" name="kinect_camera_controller">
        <alwaysOn>true</alwaysOn>
        <updateRate>0.0</updateRate>
        <cameraName>/camera</cameraName>
        <imageTopicName>image_raw</imageTopicName>
        <cameraInfoTopicName>camera_info</cameraInfoTopicName>
        <frameName>car1/camera_link</frameName>
        <hackBaseline>0.07</hackBaseline>
        <distortionK1>0.0</distortionK1>
        <distortionK2>0.0</distortionK2>
        <distortionK3>0.0</distortionK3>
        <distortionT1>0.0</distortionT1>
        <distortionT2>0.0</distortionT2>
      </plugin>
    </sensor>
  </gazebo>
  <gazebo>
    <plugin filename="libgazebo_ros_control.so" name="gazebo_ros_control">
      <robotNamespace>/car1</robotNamespace>
    </plugin>
  </gazebo>
  <gazebo reference="base_link">
    <sensor name="base_collision_sensor" type="contact">
      <always_on>true</always_on>
      <update_rate>100.0</update_rate>
      <contact>
        <!-- 尝试这几种碰撞名称格式 -->
        <collision>car1::base_link::base_link_collision</collision>
      </contact>
      <plugin filename="libgazebo_ros_bumper.so" name="base_bumper_controller">
        <bumperTopicName>/car1/bumper_states</bumperTopicName>
        <frameName>car1/base_link</frameName>
      </plugin>
    </sensor>
  </gazebo>
</robot>

